# Mastering Promise Chaining with `.then`, `.catch`, and `.finally`

Promises are a fundamental feature of asynchronous JavaScript, providing a clean and powerful way to handle asynchronous operations. Understanding how to chain `.then`, `.catch`, and `.finally` methods is essential for writing robust and error-tolerant code. This comprehensive guide explores various aspects of promise chaining using the `Promise` constructor.

## The `Promise` Constructor

The `Promise` constructor is used to create a new promise object, representing the eventual completion or failure of an asynchronous operation. The constructor takes a single function as an argument, commonly referred to as the executor function. This function is immediately invoked with two arguments: `resolve` and `reject`, which are used to fulfill or reject the promise.

```javascript
let myPromise = new Promise((resolve, reject) => {
  // Asynchronous operation
  setTimeout(() => {
    let success = true;
    if (success) {
      resolve("Operation completed successfully");
    } else {
      reject(new Error("Operation failed"));
    }
  }, 1000);
});
```

## Chaining `.then`, `.catch`, and `.finally`

### Basic Promise Chaining

Promise chaining allows us to perform sequential operations on the result of a promise. We can chain multiple `.then` methods to handle the resolved value of the promise and optionally include a single `.catch` method to handle any errors that occur during the promise chain.

```javascript
myPromise
  .then((result) => {
    console.log(result); // Outputs: Operation completed successfully
    return "Additional data";
  })
  .then((data) => {
    console.log(data); // Outputs: Additional data
  })
  .catch((error) => {
    console.error(error); // Outputs: Error: Operation failed
  });
```

### The `.finally` Method

The `.finally` method allows us to perform cleanup operations, such as releasing resources or closing connections, regardless of whether the promise is fulfilled or rejected. It is always invoked at the end of the promise chain, whether the promise is resolved, rejected, or encounters an error.

```javascript
myPromise
  .then((result) => {
    console.log(result); // Outputs: Operation completed successfully
  })
  .catch((error) => {
    console.error(error); // Outputs: Error: Operation failed
  })
  .finally(() => {
    console.log("Cleanup complete"); // Outputs: Cleanup complete
  });
```

### Combining `.then`, `.catch`, and `.finally`

We can combine `.then`, `.catch`, and `.finally` methods in various permutations to handle different scenarios in promise resolution. Here are a few examples:

```javascript
myPromise
  .then((result) => {
    console.log(result); // Outputs: Operation completed successfully
    return "Additional data";
  })
  .catch((error) => {
    console.error(error); // Outputs: Error: Operation failed
    throw new Error("Additional error");
  })
  .finally(() => {
    console.log("Cleanup complete"); // Outputs: Cleanup complete
  });
```

In this example, the `.catch` method handles the error thrown by the previous `.then` method and rethrows a new error. The `.finally` method is always executed, regardless of whether an error occurred.

### Advanced Example: Detailed Promise Chaining

Let's explore a more detailed example that demonstrates promise chaining with `.finally` before `.then`, including parameters in `.finally`, `.then`, and `.catch`.

```javascript
function fetchData(url) {
  return new Promise((resolve, reject) => {
    setTimeout(() => {
      let success = Math.random() < 0.8; // Simulate success 80% of the time
      if (success) {
        resolve(`Data fetched successfully from ${url}`);
      } else {
        reject(new Error(`Failed to fetch data from ${url}`));
      }
    }, 1000);
  });
}

fetchData("https://example.com/data")
  .finally(() => {
    console.log("Cleanup started");
  })
  .then(
    (data) => {
      console.log(data); // Outputs: Data fetched successfully from https://example.com/data
      console.log("Data processing started");
    },
    (error) => {
      console.error(error); // Outputs: Error: Failed to fetch data from https://example.com/data
      console.log("Retrying data fetch");
      return fetchData("https://example.com/data"); // Retry data fetch
    }
  )
  .then(
    (data) => {
      console.log("Data processed successfully");
    },
    (error) => {
      console.error(error); // Outputs: Error: Failed to fetch data from https://example.com/data
      console.log("Data processing failed");
    }
  )
  .catch((error) => {
    console.error(error); // Outputs: Error: Failed to fetch data from https://example.com/data
    console.log("Unable to fetch and process data");
  });
```

In this example:

- The `fetchData` function returns a promise that resolves with fetched data or rejects with an error.
- The promise chain begins with `.finally`, where cleanup tasks are performed before the promise is resolved or rejected.
- The `.then` method handles the resolved data, while the error-handling callback is triggered if the promise is rejected. The `.then` method also includes a retry mechanism by returning another promise from `fetchData`.
- The `.catch` method handles any remaining errors in the promise chain.

## Control Flow in Promise Chaining

In a promise chain with `.then`, `.catch`, and `.finally`, the control flow is determined by the resolution or rejection of the promises and the placement of these methods within the chain.

### Control Flow Breakdown

1. **Initial Promise**: The promise chain starts with an initial promise, representing an asynchronous operation. This operation may resolve with a value or reject with an error.

2. **`.then` Method**: If the initial promise is resolved, the control flow enters the first `.then` method in the chain. This method handles the resolved value and optionally returns a new value or promise. If the `.then` method returns a value, the next `.then` method in the chain is called with that value. If it returns a promise, the subsequent steps wait for that promise to resolve or reject.

3. **`.catch` Method**: If any promise in the chain rejects (including promises returned from `.then` methods), the control flow jumps to the nearest `.catch` method in the chain. The `.catch` method handles the error and optionally returns a new value or promise to continue the chain. If the `.catch` method returns a value, the subsequent steps in the chain continue with that value. If it returns a promise, the chain waits for that promise to resolve or reject.

4. **`.finally` Method**: The `.finally` method is executed regardless of whether the preceding promises are resolved or rejected. It is typically used for cleanup tasks or actions that need to be performed regardless of the outcome of the promises. The `.finally` method does not affect the control flow of the chain and does not receive any arguments from previous steps.

### Control Flow Visualization

Hereâ€™s a simplified visual representation of the control flow:

```
Initial Promise
    |
    v
.then() -> .then() -> ... -> .catch() -> .finally()
    |         |               |
    v         v               v
  resolve    resolve         reject
```

### `.then` with Two Callbacks

The `.then` method can take two callback functions as arguments:

1. The first callback handles the resolved value of the promise (success case).
2. The second callback handles the rejection of the promise (failure case).

```javascript
promise.then(
  function (value) {
    // Handle resolved value
  },
  function (error) {
    // Handle rejection reason
  }
);
```

### Control Flow with Two Callbacks

When using `.then` with two callbacks, the control flow depends on whether the promise is resolved or rejected:

- If the promise is resolved, the first callback handles the resolved value, and the control flow proceeds to the next `.then` method or `.catch` method in the chain.
- If the promise is rejected, the second callback handles the rejection, and the control flow jumps to the nearest `.catch` method in the chain.

```javascript
promise
  .then(
    function (value) {
      // Handle resolved value
      return value + 1;
    },
    function (error) {
      // Handle rejection reason
      throw new Error("Error occurred");
    }
  )
  .then(function (result) {
    // Handle result from previous .then or .catch
  })
  .catch(function (error) {
    // Handle error from previous .then or .catch
  });
```

In this example:

- If the promise is resolved, the first callback processes the value and returns a modified result.
- If the promise is rejected, the second callback processes the error and may throw a new error, which is then caught by the `.catch` method.
